<?xml version="1.0" ?>
<robot name="hanuman">
  <link name="torso">
    <inertial>
      <origin xyz="0.0 0.0 -0.029988"/>
      <!-- half mass -->
      <mass value="0.3575"/> 
      <!-- <inertia ixx="0.0005017" ixy="6.0521e-08" ixz="-7.3248e-06" iyy="0.00051292" iyz="1.1321e-10" izz="0.00095947"/> -->
    </inertial>
    <!-- <visual>
      <origin rpy="-3.14156 0 0" xyz="0 0.054 0"/>
      <geometry>
        <mesh filename="file:///home/tanawat/Documents/Thesis/Thesis_simulation/Models/hanuman04/meshes_L_fixed/torso.obj"/>
      </geometry>
    </visual>
    <collision name="torso">
      <origin rpy="-3.14156 0 0" xyz="0 0.054 0"/>
      <geometry>
        <mesh filename="file:///home/tanawat/Documents/Thesis/Thesis_simulation/Models/hanuman04/meshes_L_fixed/torso_collision.obj"/>
      </geometry>
    </collision> -->
  </link>
  <joint name="JL_hip_y" type="continuous">
    <parent link="L_hip_connector"/>
    <child link="torso"/>
    <origin rpy="0 1.5708 0" xyz="-0.03 0.000 -0.0235"/>
    <dynamics damping="0.5"/>
    <axis xyz="0 0 1"/>
    <limit effort="10.0" lower="-3.14152" upper="3.14152" velocity="0.0"/>
  </joint>
  <transmission name="trans_JL_hip_y" type="SimpleTransmission">
    <actuator name="JL_hip_y_motor">
      <mechanicalReduction>1.0</mechanicalReduction>
    </actuator>
    <joint name="JL_hip_y"/>
  </transmission>
  <link name="L_hip_connector">
    <inertial>
      <origin xyz="-0.02125 0.0 -0.0272"/>
      <mass value="0.014482"/>
      <!-- <inertia ixx="2.1782e-06" ixy="-4.5664e-11" ixz="-5.8874e-08" iyy="8.134e-06" iyz="-3.0295e-11" izz="7.6708e-06"/> -->
      <inertia ixx="7.6782e-06" ixy="-4.5664e-11" ixz="-5.8874e-08" iyy="8.134e-06" iyz="-3.0295e-11" izz="2.1708e-06"/>
    </inertial>
    <visual>
      <origin rpy="0 1.5708 0" xyz="-0.03 0.000 -0.0235"/>
      <geometry>
        <mesh filename="file:///home/tanawat/Documents/Thesis/Thesis_simulation/Models/hanuman04/meshes_L_fixed/L_hip_connector.obj"/>
      </geometry>
    </visual>
  </link>
  <joint name="JL_hip_r" type="continuous">
    <parent link="L_hip"/>
    <child link="L_hip_connector"/>
    <origin rpy="1.5708 0 0" xyz="0 -0.0235 0.0"/>
    <dynamics damping="0.5"/>
    <axis xyz="0 0 1"/>
    <limit effort="10.0" lower="-3.14152" upper="3.14152" velocity="0.0"/>
  </joint>
  <transmission name="trans_JL_hip_r" type="SimpleTransmission">
    <actuator name="JL_hip_r_motor">
      <mechanicalReduction>1.0</mechanicalReduction>
    </actuator>
    <joint name="JL_hip_r"/>
  </transmission>
  <link name="L_hip">
    <inertial>
      <origin xyz="0.014 -0.021 0.0"/>
      <mass value="0.366"/>
      <inertia ixx="5.7399e-05" ixy="1.6188e-07" ixz="-1.5552e-07" iyy="8.4262e-05" iyz="-7.6867e-21" izz="8.2055e-05"/>
    </inertial>
    <visual>
      <origin rpy="1.5708 0 0" xyz="0 -0.0235 0.0"/>
      <geometry>
        <mesh filename="file:///home/tanawat/Documents/Thesis/Thesis_simulation/Models/hanuman04/meshes_L_fixed/L_hip.obj"/>
      </geometry>
    </visual>
    <collision name="L_hip">
      <origin rpy="1.5708 0 0" xyz="0 -0.0235 0.0"/>
      <geometry>
        <mesh filename="file:///home/tanawat/Documents/Thesis/Thesis_simulation/Models/hanuman04/meshes_L_fixed/L_hip_collision.obj"/>
      </geometry>
    </collision>
  </link>
  <joint name="JL_hip_p" type="continuous">
    <parent link="L_thigh"/>
    <child link="L_hip"/>
    <origin rpy="0 0 0" xyz="-0.1605 0 0"/>
    <dynamics damping="0.5"/>
    <axis xyz="0 0 1"/>
    <limit effort="10.0" lower="-3.14152" upper="3.14152" velocity="0.0"/>
  </joint>
  <transmission name="trans_JL_hip_p" type="SimpleTransmission">
    <actuator name="JL_hip_p_motor">
      <mechanicalReduction>1.0</mechanicalReduction>
    </actuator>
    <joint name="JL_hip_p"/>
  </transmission>
  <link name="L_thigh">
    <inertial>
      <origin xyz="-0.04044 0.9823E-11 5.217E-05"/>
      <mass value="0.212"/>
      <inertia ixx="4.9123e-05" ixy="-4.775e-14" ixz="-1.6188e-07" iyy="0.00011016" iyz="-8.2973e-14" izz="8.4534e-05"/>
    </inertial>
    <visual>
      <origin rpy="0 0 0" xyz="-0.1605 0 0"/>
      <geometry>
        <mesh filename="file:///home/tanawat/Documents/Thesis/Thesis_simulation/Models/hanuman04/meshes_L_fixed/L_thigh.obj"/>
      </geometry>
    </visual>
    <collision name="L_thigh">
      <origin rpy="0 0 0" xyz="-0.1605 0 0"/>
      <geometry>
        <mesh filename="file:///home/tanawat/Documents/Thesis/Thesis_simulation/Models/hanuman04/meshes_L_fixed/L_thigh_collision.obj"/>
      </geometry>
    </collision>
  </link>
  <joint name="JL_knee" type="continuous">
    <parent link="L_leg"/>
    <child link="L_thigh"/>
    <origin rpy="0 0 -0.00" xyz="-0.166 -0.0 0"/>
    <dynamics damping="0.5"/>
    <axis xyz="0 0 1"/>
    <limit effort="10.0" lower="-3.14152" upper="3.14152" velocity="0.0"/>
  </joint>
  <transmission name="trans_JL_knee" type="SimpleTransmission">
    <actuator name="JL_knee_motor">
      <mechanicalReduction>1.0</mechanicalReduction>
    </actuator>
    <joint name="JL_knee"/>
  </transmission>
  <link name="L_leg">
    <inertial>
      <origin xyz="-0.10281 0.00777 -0.0005"/>
      <mass value="0.074194"/>
      <inertia ixx="5.5482e-05" ixy="1.6295e-05" ixz="-3.1153e-20" iyy="0.00021559" iyz="4.527e-20" izz="0.00018885"/>
    </inertial>
    <visual>
      <origin rpy="0 0 0" xyz="-0.166 -0.0 0"/>
      <geometry>
        <mesh filename="file:///home/tanawat/Documents/Thesis/Thesis_simulation/Models/hanuman04/meshes_L_fixed/L_leg.obj"/>
      </geometry>
    </visual>
  </link>
  <joint name="JL_ankle_p" type="continuous">
    <parent link="L_ankle"/>
    <child link="L_leg"/>
    <origin rpy="1.5707963267949 0 0" xyz="0 0 0.0235"/>
    <dynamics damping="0.5"/>
    <axis xyz="0 0 1"/>
    <limit effort="10.0" lower="-3.14152" upper="3.14152" velocity="0.0"/>
  </joint>
  <transmission name="trans_JL_ankle_p" type="SimpleTransmission">
    <actuator name="JL_ankle_p_motor">
      <mechanicalReduction>1.0</mechanicalReduction>
    </actuator>
    <joint name="JL_ankle_p"/>
  </transmission>
  <link name="L_ankle">
    <inertial>
      <origin xyz="-0.016972 0.00 0.00024128"/>
      <mass value="0.366"/>
      <inertia ixx="5.7399e-05" ixy="-1.5552e-07" ixz="-1.6188e-07" iyy="8.2055e-05" iyz="9.1672e-16" izz="8.4262e-05"/>
    </inertial>
    <visual>
      <origin rpy="1.5707963267949 0 0" xyz="0 0 0.0235"/>
      <geometry>
        <mesh filename="file:///home/tanawat/Documents/Thesis/Thesis_simulation/Models/hanuman04/meshes_L_fixed/L_ankle.obj"/>
      </geometry>
    </visual>
    <collision name="L_ankle">
      <origin rpy="1.5707963267949 0 0" xyz="0 0 0.0235"/>
      <geometry>
        <mesh filename="file:///home/tanawat/Documents/Thesis/Thesis_simulation/Models/hanuman04/meshes_L_fixed/L_ankle_collision.obj"/>
      </geometry>
    </collision>
  </link>
  <joint name="JL_ankle_r" type="continuous">
    <parent link="L_foot"/>
    <child link="L_ankle"/>
    <origin rpy="0 1.5707963267949 0" xyz="-0.0235 0 0.049"/>
    <dynamics damping="0.5"/>
    <axis xyz="0 0 1"/>
    <limit effort="10.0" lower="-3.14152" upper="3.14152" velocity="0.0"/>
  </joint>
  <transmission name="trans_JL_ankle_r" type="SimpleTransmission">
    <actuator name="JL_ankle_r_motor">
      <mechanicalReduction>1.0</mechanicalReduction>
    </actuator>
    <joint name="JL_ankle_r"/>
  </transmission>
  <link name="L_foot">
    <inertial>
      <origin xyz="0.034965 0.016421 0.035478"/>
      <mass value="0.14"/>
      <inertia ixx="0.00040319" ixy="2.9724e-11" ixz="2.1519e-08" iyy="0.00026502" iyz="-4.6522e-11" izz="0.00014426"/>
    </inertial>
    <visual>
      <origin rpy="0 1.5707963267949 0" xyz="-0.0235 0 0.049"/>
      <geometry>
        <mesh filename="file:///home/tanawat/Documents/Thesis/Thesis_simulation/Models/hanuman04/meshes_L_fixed/L_foot.obj"/>
      </geometry>
    </visual>
    <collision name="L_foot">
      <origin rpy="0 1.5707963267949 0" xyz="-0.0235 0 0.049"/>
      <geometry>
        <mesh filename="file:///home/tanawat/Documents/Thesis/Thesis_simulation/Models/hanuman04/meshes_L_fixed/L_foot_collision.obj"/>
      </geometry>
    </collision>
  </link>
  <link name="L_foot_contact"/>
  <joint name="L_foot_contact_offset" type="fixed">
    <parent link="L_foot_contact"/>
    <child link="L_foot"/>
    <origin rpy="0 0 0" xyz="0 0 0 "/>
  </joint>
</robot>
